<?xml version="1.0"?>
<!-- Revolute-Revolute Manipulator -->
<robot name="rrbot" xmlns:xacro="http://www.ros.org/wiki/xacro">

  <!-- Constants for robot dimensions -->
  <xacro:property name="PI" value="3.1415926535897931"/>
  <xacro:property name="mass" value="1" /> <!-- arbitrary value for mass -->
  <xacro:property name="width" value="0.1" /> <!-- Square dimensions (widthxwidth) of beams -->
  <xacro:property name="height1" value="2" /> <!-- Link 1 -->
  <xacro:property name="height2" value="1" /> <!-- Link 2 -->
  <xacro:property name="height3" value="1" /> <!-- Link 3 -->
  <xacro:property name="camera_link" value="0.05" /> <!-- Size of square 'camera' box -->
  <xacro:property name="axel_offset" value="0.05" /> <!-- Space btw top of beam and the each joint -->

  <!-- Import all Gazebo-customization elements, including Gazebo colors -->
  <xacro:include filename="$(find rrbot_description)/urdf/rrbot.gazebo" />
  <!-- Import Rviz colors -->
  <xacro:include filename="$(find rrbot_description)/urdf/materials.xacro" />

  <!-- Used for fixing robot to Gazebo 'base_link' -->
  <link name="world"/>

  <joint name="fixed" type="fixed">
    <parent link="world"/>
    <child link="base"/>
  </joint>

  <!-- base -->
  <link name="base">
    <collision>
      <origin xyz="0 0 0.05" rpy="0 0 0"/>
      <geometry>
	<box size="0.1 0.1 0.1"/>
      </geometry>
    </collision>

    <visual>
      <origin xyz="0 0 0.05" rpy="0 0 0"/>
      <geometry>
	<box size="0.1 0.1 0.1"/>
      </geometry>
      <material name="orange"/>
    </visual>

    <inertial>
      <origin xyz="0 0 0" rpy="0 0 0"/>
      <mass value="${mass}"/>
      <inertia
	  ixx="${mass / 12.0 * (width*width + height1*height1)}" ixy="0.0" ixz="0.0"
	  iyy="${mass / 12.0 * (height1*height1 + width*width)}" iyz="0.0"
	  izz="${mass / 12.0 * (width*width + width*width)}"/>
    </inertial>
  </link>

  <joint name="base_joint" type="continuous">
    <parent link="base"/>
    <child link="link1"/>
    <origin xyz="0 0 0" rpy="0 0 0"/>
    <axis xyz="0 0 1"/>
    <dynamics damping="0.7"/>
  </joint>

  <!-- link1 -->
  <link name="link1">
    <collision>
      <origin xyz="-0.039 0.042 0.18" rpy="1.57 1.57 0"/>
      <geometry>
	<mesh filename="package://arm_description/meshes/collision/shoulderconnector1.dae" scale="0.001 0.001 0.001"/>
      </geometry>
    </collision>

    <visual>
      <origin xyz="-0.039 0.042 0.18" rpy="1.57 1.57 0"/>
      <geometry>
	<mesh filename="package://arm_description/meshes/visual/shoulderconnector1.dae" scale="0.001 0.001 0.001"/>
      </geometry>
      <material name="orange"/>
    </visual>

    <inertial>
      <origin xyz="0 0 0" rpy="0 0 0"/>
      <mass value="${mass}"/>
      <inertia
	  ixx="${mass / 12.0 * (width*width + height1*height1)}" ixy="0.0" ixz="0.0"
	  iyy="${mass / 12.0 * (height1*height1 + width*width)}" iyz="0.0"
	  izz="${mass / 12.0 * (width*width + width*width)}"/>
    </inertial>
  </link>

  <joint name="joint1" type="continuous">
    <parent link="link1"/>
    <child link="link2"/>
    <origin xyz="0 0 0.18" rpy="0 0 0"/>
    <axis xyz="0 1 0"/>
    <dynamics damping="0.7"/>
  </joint>

  <!-- link2 -->
  <link name="link2">
    <collision>
      <origin xyz="0 0 0.02" rpy="0 1.56 0"/>
      <geometry>
	<mesh filename="package://arm_description/meshes/collision/shoulderconnector2.dae" scale="0.001 0.001 0.001"/>
      </geometry>
    </collision>

    <visual>
      <origin xyz="0 0 0.02" rpy="0 1.56 0"/>
      <geometry>
        <mesh filename="package://arm_description/meshes/visual/shoulderconnector2.dae" scale="0.001 0.001 0.001"/>
      </geometry>
      <material name="orange"/>
    </visual>

    <inertial>
      <origin xyz="0 0 0" rpy="1.56 0 0"/>
      <mass value="${mass}"/>
      <inertia
	  ixx="${mass / 12.0 * (width*width + height2*height2)}" ixy="0.0" ixz="0.0"
	  iyy="${mass / 12.0 * (height2*height2 + width*width)}" iyz="0.0"
	  izz="${mass / 12.0 * (width*width + width*width)}"/>
    </inertial>
  </link>

  <joint name="joint2" type="continuous">
    <parent link="link2"/>
    <child link="link3"/>
    <origin xyz="0 0 0.05" rpy="0 0 0"/>
    <axis xyz="1 0 0"/>
    <dynamics damping="0.7"/>
  </joint>

  <!-- link3 -->
  <link name="link3">
    <collision>
      <origin xyz="0.04 0.04 0.2" rpy="1.57 3.14 0"/>
      <geometry>
	<mesh filename="package://arm_description/meshes/collision/upper_arm.dae" scale="0.001 0.001 0.001"/>
      </geometry>
    </collision>

    <visual>
      <origin xyz="0.04 0.04 0.2" rpy="1.57 3.14 0"/>
      <geometry>
        <mesh filename="package://arm_description/meshes/visual/upper_arm.dae" scale="0.001 0.001 0.001"/>
      </geometry>
      <material name="black"/>
    </visual>

    <inertial>
      <origin xyz="0 0 0" rpy="1.56 0 0"/>
      <mass value="${mass}"/>
      <inertia
	  ixx="${mass / 12.0 * (width*width + height2*height2)}" ixy="0.0" ixz="0.0"
	  iyy="${mass / 12.0 * (height2*height2 + width*width)}" iyz="0.0"
	  izz="${mass / 12.0 * (width*width + width*width)}"/>
    </inertial>
  </link>
  
  <joint name="joint3" type="continuous">
    <parent link="link3"/>
    <child link="link4"/>
    <origin xyz="0 0 0.18" rpy="0 0 0"/>
    <axis xyz="1 0 0"/>
    <dynamics damping="0.7"/>
  </joint>

  <!-- link4 -->
  <link name="link4">
    <collision>
      <origin xyz="0.04 0.035 0.24" rpy="-1.57 0 3.14"/>
      <geometry>
	<mesh filename="package://arm_description/meshes/collision/forearm.dae" scale="0.001 0.001 0.001"/>
      </geometry>
    </collision>

    <visual>
      <origin xyz="0.04 0.035 0.24" rpy="-1.57 0 3.14"/>
      <geometry>
        <mesh filename="package://arm_description/meshes/visual/forearm.dae" scale="0.001 0.001 0.001"/>
      </geometry>
      <material name="black"/>
    </visual>

    <inertial>
      <origin xyz="0 0 0" rpy="1.56 0 0"/>
      <mass value="${mass}"/>
      <inertia
	  ixx="${mass / 12.0 * (width*width + height2*height2)}" ixy="0.0" ixz="0.0"
	  iyy="${mass / 12.0 * (height2*height2 + width*width)}" iyz="0.0"
	  izz="${mass / 12.0 * (width*width + width*width)}"/>
    </inertial>
  </link>

</robot>
